<?xml version="1.0" encoding="utf-8"?>
<!-- This URDF was automatically created by SolidWorks to URDF Exporter! Originally created by Stephen Brawner (brawner@gmail.com) 
     Commit Version: 1.6.0-4-g7f85cfe  Build Version: 1.6.7995.38578
     For more information, please see http://wiki.ros.org/sw_urdf_exporter -->
<robot
  name="left">
  
  
   <link name="world"/>
  
  
  
  <joint name="base_joint" type="fixed">
	<parent link="world"/>
	<child link="base_link"/>
	<origin rpy="0 0 0" xyz="0.0 0.0 1"/>
  </joint>  
  
  <link
    name="base_link">
    <inertial>
      <origin
        xyz="0.000333168231091308 -0.0490077134325242 0.105556739128517"
        rpy="0 0 0" />
      <mass
        value="0.43756889593348" />
      <inertia
        ixx="0.000780173945392212"
        ixy="1.72547696446316E-06"
        ixz="-8.11722846382814E-08"
        iyy="0.000825842165328829"
        iyz="4.67151417985947E-05"
        izz="0.000643183765667985" />
    </inertial>
    <visual>
      <origin
        xyz="0 0 0"
        rpy="0 0 0" />
      <geometry>
        <mesh
          filename="package://left/meshes/base_link.STL" />
      </geometry>
      <material
        name="">
        <color
          rgba="1 1 1 1" />
      </material>
    </visual>
    <collision>
      <origin
        xyz="0 0 0"
        rpy="0 0 0" />
      <geometry>
        <mesh
          filename="package://left/meshes/base_link.STL" />
      </geometry>
    </collision>
  </link>
  <link
    name="left_up_joint">
    <inertial>
      <origin
        xyz="-5.09595435294052E-10 -7.24041521182883E-10 -0.0157092653420776"
        rpy="0 0 0" />
      <mass
        value="0.0208133468453592" />
      <inertia
        ixx="6.27974968154287E-06"
        ixy="-1.32343047861604E-11"
        ixz="-8.95773959812006E-14"
        iyy="1.11423800240112E-05"
        iyz="-1.2794410246771E-13"
        izz="8.2135527700594E-06" />
    </inertial>
    <visual>
      <origin
        xyz="0 0 0"
        rpy="0 0 0" />
      <geometry>
        <mesh
          filename="package://left/meshes/left_up_joint.STL" />
      </geometry>
      <material
        name="">
        <color
          rgba="0.792156862745098 0.819607843137255 0.933333333333333 1" />
      </material>
    </visual>
    <collision>
      <origin
        xyz="0 0 0"
        rpy="0 0 0" />
      <geometry>
        <mesh
          filename="package://left/meshes/left_up_joint.STL" />
      </geometry>
    </collision>
  </link>
  <joint
    name="l1"
    type="revolute">
    <origin
      xyz="-0.0936387883044479 -0.0510621773979172 0.130726931673384"
      rpy="-1.5707963267949 0 1.5707963267949" />
    <parent
      link="base_link" />
    <child
      link="left_up_joint" />
    <axis
      xyz="0 0 1" />
    <limit
      lower="-3.14"
      upper="3.14"
      effort="100"
      velocity="1" />
  </joint>
  <link
    name="left_up_arm">
    <inertial>
      <origin
        xyz="0.0373903260955437 6.01721482867967E-05 -0.00541151025560828"
        rpy="0 0 0" />
      <mass
        value="0.142004365290477" />
      <inertia
        ixx="3.19807239576317E-05"
        ixy="-4.35320002639632E-08"
        ixz="2.24405433812155E-06"
        iyy="6.16421105939794E-05"
        iyz="9.81629533561359E-10"
        izz="6.84742764155625E-05" />
    </inertial>
    <visual>
      <origin
        xyz="0 0 0"
        rpy="0 0 0" />
      <geometry>
        <mesh
          filename="package://left/meshes/left_up_arm.STL" />
      </geometry>
      <material
        name="">
        <color
          rgba="0.752941176470588 0.752941176470588 0.752941176470588 1" />
      </material>
    </visual>
    <collision>
      <origin
        xyz="0 0 0"
        rpy="0 0 0" />
      <geometry>
        <mesh
          filename="package://left/meshes/left_up_arm.STL" />
      </geometry>
    </collision>
  </link>
  <joint
    name="l2"
    type="revolute">
    <origin
      xyz="0 0 0"
      rpy="1.5707963267949 0 1.57079632679489" />
    <parent
      link="left_up_joint" />
    <child
      link="left_up_arm" />
    <axis
      xyz="0 0 -1" />
    <limit
      lower="-3.14"
      upper="3.14"
      effort="100"
      velocity="1" />
  </joint>
  <link
    name="left_low_joint">
    <inertial>
      <origin
        xyz="2.22044604925031E-16 -2.85966136187588E-10 -0.0157092656103693"
        rpy="0 0 0" />
      <mass
        value="0.0208133475595526" />
      <inertia
        ixx="6.27974985366218E-06"
        ixy="-1.33778831812525E-11"
        ixz="1.17235207133201E-19"
        iyy="1.114238023727E-05"
        iyz="-4.94677558464213E-14"
        izz="8.21355305611453E-06" />
    </inertial>
    <visual>
      <origin
        xyz="0 0 0"
        rpy="0 0 0" />
      <geometry>
        <mesh
          filename="package://left/meshes/left_low_joint.STL" />
      </geometry>
      <material
        name="">
        <color
          rgba="0.792156862745098 0.819607843137255 0.933333333333333 1" />
      </material>
    </visual>
    <collision>
      <origin
        xyz="0 0 0"
        rpy="0 0 0" />
      <geometry>
        <mesh
          filename="package://left/meshes/left_low_joint.STL" />
      </geometry>
    </collision>
  </link>
  <joint
    name="l3"
    type="revolute">
    <origin
      xyz="0.117 0 -0.00100000000000006"
      rpy="-1.5707963267949 0 -1.5707963267949" />
    <parent
      link="left_up_arm" />
    <child
      link="left_low_joint" />
    <axis
      xyz="0 0 1" />
    <limit
      lower="-3.14"
      upper="3.14"
      effort="100"
      velocity="1" />
  </joint>
  <link
    name="left_low_arm">
    <inertial>
      <origin
        xyz="0.0481196273812194 -0.000145349329483678 0.000141021295786303"
        rpy="0 0 0" />
      <mass
        value="0.189033643696219" />
      <inertia
        ixx="7.6979741225698E-05"
        ixy="-3.38641336425108E-07"
        ixz="-3.25828337644159E-09"
        iyy="8.21074310058178E-05"
        iyz="-5.51403520464928E-07"
        izz="0.000103326261719523" />
    </inertial>
    <visual>
      <origin
        xyz="0 0 0"
        rpy="0 0 0" />
      <geometry>
        <mesh
          filename="package://left/meshes/left_low_arm.STL" />
      </geometry>
      <material
        name="">
        <color
          rgba="0.752941176470588 0.752941176470588 0.752941176470588 1" />
      </material>
    </visual>
    <collision>
      <origin
        xyz="0 0 0"
        rpy="0 0 0" />
      <geometry>
        <mesh
          filename="package://left/meshes/left_low_arm.STL" />
      </geometry>
    </collision>
  </link>
  <joint
    name="l4"
    type="revolute">
    <origin
      xyz="0 0 0"
      rpy="-1.5707963267949 0 -1.5707963267949" />
    <parent
      link="left_low_joint" />
    <child
      link="left_low_arm" />
    <axis
      xyz="0 0 -1" />
    <limit
      lower="-3.14"
      upper="3.14"
      effort="100"
      velocity="1" />
  </joint>
  <link
    name="left_gripper">
    <inertial>
      <origin
        xyz="0.00394028289479496 -0.0216328066989446 -0.000648626674703112"
        rpy="0 0 0" />
      <mass
        value="0.103299324219439" />
      <inertia
        ixx="2.09630043696831E-05"
        ixy="-3.12167035365805E-07"
        ixz="-2.90752267814506E-08"
        iyy="2.33522908570638E-05"
        iyz="-1.75561004581678E-08"
        izz="1.89319959235233E-05" />
    </inertial>
    <visual>
      <origin
        xyz="0 0 0"
        rpy="0 0 0" />
      <geometry>
        <mesh
          filename="package://left/meshes/left_gripper.STL" />
      </geometry>
      <material
        name="">
        <color
          rgba="0.752941176470588 0.752941176470588 0.752941176470588 1" />
      </material>
    </visual>
    <collision>
      <origin
        xyz="0 0 0"
        rpy="0 0 0" />
      <geometry>
        <mesh
          filename="package://left/meshes/left_gripper.STL" />
      </geometry>
    </collision>
  </link>
  <joint
    name="l5"
    type="fixed">
    <origin
      xyz="0.15114001564623 0.000250000152477973 -0.000500000000000389"
      rpy="-3.14159265358979 0 1.5707963267949" />
    <parent
      link="left_low_arm" />
    <child
      link="left_gripper" />
    <axis
      xyz="0 0 0" />
  </joint>
  
  <transmission name="left_up_joint_trans">
	<type>transmission_interface/SimpleTransmission</type>
	<joint name="l1">
		<hardwareInterface>hardware_interface/PositionJointInterface</hardwareInterface>
	</joint>
	<actuator name="left_up_joint_motor">
		<hardwareInterface>hardware_interface/PositionJointInterface</hardwareInterface>
		<mechanicalReduction>1</mechanicalReduction>
	</actuator>
  </transmission>
  
  <transmission name="left_up_arm_trans">
	<type>transmission_interface/SimpleTransmission</type>
	<joint name="l2">
		<hardwareInterface>hardware_interface/PositionJointInterface</hardwareInterface>
	</joint>
	<actuator name="left_up_arm_motor">
		<hardwareInterface>hardware_interface/PositionJointInterface</hardwareInterface>
		<mechanicalReduction>1</mechanicalReduction>
	</actuator>
  </transmission>
  
  <transmission name="left_low_joint_trans">
	<type>transmission_interface/SimpleTransmission</type>
	<joint name="l3">
		<hardwareInterface>hardware_interface/PositionJointInterface</hardwareInterface>
	</joint>
	<actuator name="left_low_joint_motor">
		<hardwareInterface>hardware_interface/PositionJointInterface</hardwareInterface>
		<mechanicalReduction>1</mechanicalReduction>
	</actuator>
  </transmission>
  
  <transmission name="left_low_arm_trans">
	<type>transmission_interface/SimpleTransmission</type>
	<joint name="l4">
		<hardwareInterface>hardware_interface/PositionJointInterface</hardwareInterface>
	</joint>
	<actuator name="left_low_arm_motor">
		<hardwareInterface>hardware_interface/PositionJointInterface</hardwareInterface>
		<mechanicalReduction>1</mechanicalReduction>
	</actuator>
  </transmission>  
   <gazebo>
	<plugin name="control" filename="libgazebo_ros_control.so">
		<robotNamespace>/</robotNamespace>
	</plugin>
  </gazebo>
  
  
  <gazebo reference="left_up_joint">
	<selfCollide>true</selfCollide>
  </gazebo>

  <gazebo reference="left_up_arm">
	<selfCollide>true</selfCollide>
  </gazebo>
  
  <gazebo reference="left_low_joint">
	<selfCollide>true</selfCollide>
  </gazebo>
  
    <gazebo reference="left_low_arm">
	<selfCollide>true</selfCollide>
  </gazebo>
  
  
</robot>
